<mujoco model="ant">
  <compiler angle="degree" coordinate="local" inertiafromgeom="true"/>
  <option integrator="RK4" timestep="0.01"/>
  <custom>
    <numeric data="0.0 0.0 0.55 1.0 0.0 0.0 0.0 0.0 1.0 0.0 -1.0 0.0 -1.0 0.0 1.0" name="init_qpos"/>
  </custom>
  <default>
    <joint armature="1" damping="1" limited="true"/>
    <geom conaffinity="0" condim="3" density="5.0" friction="1 0.5 0.5" margin="0.01" rgba="0.8 0.6 0.4 1"/>
  </default>
  <asset>
    <texture builtin="gradient" height="100" rgb1="1 1 1" rgb2="0 0 0" type="skybox" width="100"/>
    <texture builtin="flat" height="1278" mark="cross" markrgb="1 1 1" name="texgeom" random="0.01" rgb1="0.8 0.6 0.4" rgb2="0.8 0.6 0.4" type="cube" width="127"/>
    <texture builtin="checker" height="100" name="texplane" rgb1="0 0 0" rgb2="0.8 0.8 0.8" type="2d" width="100"/>
    <material name="MatPlane" reflectance="0.5" shininess="1" specular="1" texrepeat="60 60" texture="texplane"/>
    <material name="geom" texture="texgeom" texuniform="true"/>
  </asset>
  <worldbody>
    <light cutoff="100" diffuse="1 1 1" dir="-0 0 -1.3" directional="true" exponent="1" pos="0 0 1.3" specular=".1 .1 .1"/>
    <geom conaffinity="1" condim="3" material="MatPlane" name="floor" pos="0 0 0" rgba="0.8 0.9 0.8 1" size="40 40 40" type="plane"/>

    <geom name="block0" type="box" pos="3.5 0 0.06" size="0.7 8 0.06" rgba="0.3 0.2 0.8 1" contype="1" conaffinity="1" density="0"/>
    <geom name="block1" type="box" pos="4.6 0 0.18" size="0.7 8 0.06" rgba="0.1 0.3 0.6 1" contype="1" conaffinity="1" density="0"/>
    <geom name="block2" type="box" pos="5.8 0 0.32" size="0.7 8 0.08" rgba="0.2 0.4 0.4 1" contype="1" conaffinity="1" density="0"/>
    <geom name="block3" type="box" pos="7.0 0 0.18" size="0.7 8 0.06" rgba="0.2 0.6 0.2 1" contype="1" conaffinity="1" density="0"/>
    <geom name="block4" type="box" pos="8.1 0 0.06" size="0.7 8 0.06" rgba="0.2 0.7 0.1 1" contype="1" conaffinity="1" density="0"/>

    <geom name="block5" type="box" pos="10.5 0 0.04" size="0.7 8 0.04" rgba="0.3 0.2 0.8 1" contype="1" conaffinity="1" density="0"/>
    <geom name="block6" type="box" pos="11.5 0 0.12" size="0.7 8 0.04" rgba="0.1 0.3 0.6 1" contype="1" conaffinity="1" density="0"/>
    <geom name="block7" type="box" pos="12.7 0 0.23" size="0.7 8 0.07" rgba="0.2 0.4 0.4 1" contype="1" conaffinity="1" density="0"/>
    <geom name="block8" type="box" pos="13.8 0 0.11" size="0.7 8 0.05" rgba="0.2 0.6 0.2 1" contype="1" conaffinity="1" density="0"/>
    <geom name="block9" type="box" pos="14.8 0 0.03" size="0.7 8 0.03" rgba="0.3 0.5 0.3 1" contype="1" conaffinity="1" density="0"/>

    <geom name="block10" type="box" pos="17.1 0 0.05" size="0.7 8 0.05" rgba="0.3 0.2 0.8 1" contype="1" conaffinity="1" density="0"/>
    <geom name="block11" type="box" pos="18.1 0 0.15" size="0.7 8 0.05" rgba="0.1 0.3 0.6 1" contype="1" conaffinity="1" density="0"/>
    <geom name="block12" type="box" pos="19.3 0 0.25" size="0.7 8 0.05" rgba="0.2 0.4 0.4 1" contype="1" conaffinity="1" density="0"/>
    <geom name="block13" type="box" pos="20.5 0 0.15" size="0.7 8 0.05" rgba="0.2 0.6 0.2 1" contype="1" conaffinity="1" density="0"/>
    <geom name="block14" type="box" pos="21.5 0 0.05" size="0.7 8 0.05" rgba="0.3 0.5 0.3 1" contype="1" conaffinity="1" density="0"/>

    <geom name="block15" type="box" pos="23.6 0 0.03" size="0.7 8 0.03" rgba="0.3 0.2 0.8 1" contype="1" conaffinity="1" density="0"/>
    <geom name="block16" type="box" pos="24.6 0 0.11" size="0.7 8 0.05" rgba="0.1 0.3 0.6 1" contype="1" conaffinity="1" density="0"/>
    <geom name="block17" type="box" pos="25.8 0 0.23" size="0.7 8 0.07" rgba="0.2 0.4 0.4 1" contype="1" conaffinity="1" density="0"/>
    <geom name="block18" type="box" pos="27.0 0 0.12" size="0.7 8 0.04" rgba="0.2 0.6 0.2 1" contype="1" conaffinity="1" density="0"/>
    <geom name="block19" type="box" pos="28.0 0 0.04" size="0.7 8 0.04" rgba="0.3 0.5 0.1 1" contype="1" conaffinity="1" density="0"/>

    <geom name="WallTop" type="box" pos="10.0 8.5 0.5" size="40 0.5 0.8" rgba="0.2 0.6 0.2 1" contype="1" conaffinity="1" density="0"/>
    <geom name="WallBot" type="box" pos="10.0 -8.5 0.5" size="40 0.5 0.8" rgba="0.2 0.7 0.1 1" contype="1" conaffinity="1" density="0"/>

    <body name="torso" pos="0 0 0.75">
      <!-- <camera name="track" mode="trackcom" pos="15.5 -35 20" xyaxes="1 0 0 0 0.7 1"/> -->
      <!-- <camera name="track" mode="trackcom" pos="15 0 40" xyaxes="1 0 0 0 1 0"/> -->
      <camera name="track" mode="trackcom" pos="0.5 -4 0.5" xyaxes="1 0 0 0 0.05 1"/>

      <geom name="torso_geom" pos="0 0 0" size="0.25" type="sphere"/>
      <joint armature="0" damping="0" limited="false" margin="0.01" name="root" pos="0 0 0" type="free"/>
      
      <body name="front_left_leg" pos="0 0 0">
        <geom fromto="0.0 0.0 0.0 0.2 0.2 0.0" name="aux_1_geom" size="0.08" type="capsule"/>
        <body name="aux_1" pos="0.2 0.2 0">
          <joint axis="0 0 1" name="hip_1" pos="0.0 0.0 0.0" range="-30 30" type="hinge"/>
          <geom fromto="0.0 0.0 0.0 0.2 0.2 0.0" name="left_leg_geom" size="0.08" type="capsule"/>
          <body pos="0.2 0.2 0">
            <joint axis="-1 1 0" name="ankle_1" pos="0.0 0.0 0.0" range="30 70" type="hinge"/>
            <geom fromto="0.0 0.0 0.0 0.4 0.4 0.0" name="left_ankle_geom" size="0.08" type="capsule"/>
          </body>
        </body>
      </body>
      <body name="front_right_leg" pos="0 0 0">
        <geom fromto="0.0 0.0 0.0 -0.2 0.2 0.0" name="aux_2_geom" size="0.08" type="capsule"/>
        <body name="aux_2" pos="-0.2 0.2 0">
          <joint axis="0 0 1" name="hip_2" pos="0.0 0.0 0.0" range="-30 30" type="hinge"/>
          <geom fromto="0.0 0.0 0.0 -0.2 0.2 0.0" name="right_leg_geom" size="0.08" type="capsule"/>
          <body pos="-0.2 0.2 0">
            <joint axis="1 1 0" name="ankle_2" pos="0.0 0.0 0.0" range="-70 -30" type="hinge"/>
            <geom fromto="0.0 0.0 0.0 -0.4 0.4 0.0" name="right_ankle_geom" size="0.08" type="capsule"/>
          </body>
        </body>
      </body>
      <body name="back_leg" pos="0 0 0">
        <geom fromto="0.0 0.0 0.0 -0.2 -0.2 0.0" name="aux_3_geom" size="0.08" type="capsule"/>
        <body name="aux_3" pos="-0.2 -0.2 0">
          <joint axis="0 0 1" name="hip_3" pos="0.0 0.0 0.0" range="-30 30" type="hinge"/>
          <geom fromto="0.0 0.0 0.0 -0.2 -0.2 0.0" name="back_leg_geom" size="0.08" type="capsule"/>
          <body pos="-0.2 -0.2 0">
            <joint axis="-1 1 0" name="ankle_3" pos="0.0 0.0 0.0" range="-70 -30" type="hinge"/>
            <geom fromto="0.0 0.0 0.0 -0.4 -0.4 0.0" name="third_ankle_geom" size="0.08" type="capsule"/>
          </body>
        </body>
      </body>
      <body name="right_back_leg" pos="0 0 0">
        <geom fromto="0.0 0.0 0.0 0.2 -0.2 0.0" name="aux_4_geom" size="0.08" type="capsule"/>
        <body name="aux_4" pos="0.2 -0.2 0">
          <joint axis="0 0 1" name="hip_4" pos="0.0 0.0 0.0" range="-30 30" type="hinge"/>
          <geom fromto="0.0 0.0 0.0 0.2 -0.2 0.0" name="rightback_leg_geom" size="0.08" type="capsule"/>
          <body pos="0.2 -0.2 0">
            <joint axis="1 1 0" name="ankle_4" pos="0.0 0.0 0.0" range="30 70" type="hinge"/>
            <geom fromto="0.0 0.0 0.0 0.4 -0.4 0.0" name="fourth_ankle_geom" size="0.08" type="capsule"/>
          </body>
        </body>
      </body>
    </body>
  </worldbody>
  <actuator>
    <motor ctrllimited="true" ctrlrange="-1.0 1.0" joint="hip_4" gear="150"/>
    <motor ctrllimited="true" ctrlrange="-1.0 1.0" joint="ankle_4" gear="150"/>
    <motor ctrllimited="true" ctrlrange="-1.0 1.0" joint="hip_1" gear="150"/>
    <motor ctrllimited="true" ctrlrange="-1.0 1.0" joint="ankle_1" gear="150"/>
    <motor ctrllimited="true" ctrlrange="-1.0 1.0" joint="hip_2" gear="150"/>
    <motor ctrllimited="true" ctrlrange="-1.0 1.0" joint="ankle_2" gear="150"/>
    <motor ctrllimited="true" ctrlrange="-1.0 1.0" joint="hip_3" gear="150"/>
    <motor ctrllimited="true" ctrlrange="-1.0 1.0" joint="ankle_3" gear="150"/>
  </actuator>
</mujoco>
